Workbook

Sheet Time Standards
A1: LED MIRROR — ASSEMBLY TIME STANDARDS
A2: Blue cells are editable inputs. All times in minutes.
A3: STEP # | B3: OPERATION | C3: STD TIME (min) | D3: BEST CASE (min) | E3: WORST CASE (min) | F3: NOTES
B4: LANE 1 — FRAME
A5: F1 | B5: Cut 2x4s to rough length | C5: 3 | D5: 2 | E5: 5 | F5: Per frame; batch cutting saves setup time
A6: F2 | B6: Mill profiles — standard segments | C6: 5 | D6: 4 | E6: 8 | F6: Router table; all identical segments
A7: F3 | B7: Mill electronics pocket segment | C7: 7 | D7: 5 | E7: 10 | F7: Dedicated fixture; one per frame
A8: F4 | B8: Miter & glue assembly | C8: 8 | D8: 6 | E8: 14 | F8: Jig essential — do not freehand
A9: F5 | B9: Clamp & cure wait | C9: 0.5 | D9: 0.5 | E9: 0.5 | F9: Active time only; glue cures passively
A10: F6 | B10: Sand & finish pass | C10: 4 | D10: 3 | E10: 6 | F10: Light pass before final assembly
A11: F7 | B11: Frame QC — square & joints | C11: 2 | D11: 1 | E11: 3 | F11: Check square, pocket dims, joint tightness
B12: ↳ LANE 1 — FRAME SUBTOTAL | C12: =SUM(C5:C11) | D12: =SUM(D5:D11) | E12: =SUM(E5:E11)
B14: LANE 2 — MIRRORS
A15: M1 | B15: Batch cut 12x12 sheet → 4x 6x6 | C15: 4 | D15: 3 | E15: 6 | F15: Wet saw; amortized per sheet (÷4 for per unit)
A16: M2 | B16: Edge inspection & clean | C16: 1.5 | D16: 1 | E16: 3 | F16: Check for chips; wipe clean
A17: M3 | B17: Custom design cut (if applicable) | C17: 6 | D17: 4 | E17: 12 | F17: Laser or CNC; skip for blank units
A18: M4 | B18: Mirror QC — clarity & edges | C18: 1.5 | D18: 1 | E18: 2 | F18: Inspect both panels before assembly
B19: ↳ LANE 2 — MIRRORS SUBTOTAL | C19: =SUM(C15:C18) | D19: =SUM(D15:D18) | E19: =SUM(E15:E18)
B21: LANE 3A — LED STRIP PREP
A22: E1 | B22: Incoming test (full strip pre-cut) | C22: 2 | D22: 1.5 | E22: 3 | F22: Bench PSU + test harness; reject bad strips
A23: E2 | B23: Cut strip to spec length | C23: 1.5 | D23: 1 | E23: 2 | F23: Score and snap on cut line
A24: E3 | B24: Solder connector — VIN pad | C24: 3 | D24: 2 | E24: 5 | F24: Hakko iron; fine tip; flux first
A25: E4 | B25: Solder connector — GND pad | C25: 3 | D25: 2 | E25: 5 | F25: Inspect joint under loupe
A26: E5 | B26: Solder connector — DATA pad | C26: 3 | D26: 2 | E26: 5 | F26: Most critical joint — verify continuity
A27: E6 | B27: Post-solder power-on test | C27: 2 | D27: 1.5 | E27: 3 | F27: All LEDs must fire before proceeding
A28: E7 | B28: Seat strip into 3D printed spacer | C28: 2 | D28: 1.5 | E28: 3 | F28: Press fit; check alignment
B29: ↳ LANE 3A — LED STRIP PREP SUBTOTAL | C29: =SUM(C22:C28) | D29: =SUM(D22:D28) | E29: =SUM(E22:E28)
B31: LANE 3B — CONTROLLER PREP
A32: C1 | B32: Receive & inspect controller | C32: 1.5 | D32: 1 | E32: 3 | F32: Check for physical damage; ESD precautions
A33: C2 | B33: Flash firmware (per unit, batched) | C33: 3 | D33: 2 | E33: 5 | F33: Pi jig; batch 5-10 at once to amortize setup
A34: C3 | B34: Solder required pads/through-hole | C34: 5 | D34: 3.5 | E34: 8 | F34: Per controller BOM; inspect all joints
A35: C4 | B35: Controller function test | C35: 2 | D35: 1.5 | E35: 3 | F35: Power on, verify comms & output
A36: C5 | B36: Seat controller into 3D housing | C36: 1.5 | D36: 1 | E36: 2 | F36: Press fit; secure if needed
B37: ↳ LANE 3B — CONTROLLER PREP SUBTOTAL | C37: =SUM(C32:C36) | D37: =SUM(D32:D36) | E37: =SUM(E32:E36)
B39: FINAL ASSEMBLY
A40: A1 | B40: Kit check — all sub-assemblies present | C40: 1.5 | D40: 1 | E40: 2 | F40: Traveler card sign-off before starting
A41: A2 | B41: Install controller housing into pocket | C41: 3 | D41: 2 | E41: 4 | F41: Secure; verify cable routing path
A42: A3 | B42: Lay mirror #1 into milled channels | C42: 2 | D42: 1.5 | E42: 3 | F42: Handle with suction cups; no fingerprints
A43: A4 | B43: Seat LED strip assembly | C43: 2 | D43: 1.5 | E43: 3 | F43: Align to mirror edge; route cable
A44: A5 | B44: Lay mirror #2 | C44: 2 | D44: 1.5 | E44: 3 | F44: Verify alignment and spacing
...

Sheet Unit Calculator
A1: LED MIRROR — UNIT TIME CALCULATOR & DASHBOARD
A2: Adjust batch size and custom mirror flag. All times pull live from Time Standards sheet.
B3: INPUTS
B4: Batch Size (units per run) | C4: 10 | D4: Number of units built per production batch
B5: Orders per Day | C5: 1 | D5: Target daily output
B6: Include Custom Mirror Cut? | C6: 1 | D6: 1 = Yes (custom design), 0 = No (blank unit)
B7: Operator Efficiency Factor | C7: 0.85 | D7: 1.0 = perfect; 0.85 = realistic for trained operator
B8: Hourly Labor Rate ($/hr) | C8: 25 | D8: Fully-loaded operator cost
B10: PER-UNIT TIME SUMMARY
B11: LANE / OPERATION | C11: STD (min) | D11: BEST (min) | E11: WORST (min) | F11: STD (hrs) | G11: LABOR COST ($)
B12: Frame | C12: ='Time Standards'!C12 | D12: ='Time Standards'!D12 | E12: ='Time Standards'!E12 | F12: =C12/60 | G12: =F12*$C$8
B13: Mirrors | C13: ='Time Standards'!C19 | D13: ='Time Standards'!D19 | E13: ='Time Standards'!E19 | F13: =C13/60 | G13: =F13*$C$8
B14: LED Strip Prep | C14: ='Time Standards'!C29 | D14: ='Time Standards'!D29 | E14: ='Time Standards'!E29 | F14: =C14/60 | G14: =F14*$C$8
B15: Controller Prep | C15: ='Time Standards'!C37 | D15: ='Time Standards'!D37 | E15: ='Time Standards'!E37 | F15: =C15/60 | G15: =F15*$C$8
B16: Final Assembly | C16: ='Time Standards'!C50 | D16: ='Time Standards'!D50 | E16: ='Time Standards'!E50 | F16: =C16/60 | G16: =F16*$C$8
B17: SUBTOTAL (raw) | C17: =SUM(C12:C16) | D17: =SUM(D12:D16) | E17: =SUM(E12:E16) | F17: =SUM(F12:F16) | G17: =SUM(G12:G16)
B18: ADJUSTED (÷ efficiency factor) | C18: =C17/$C$7 | D18: =D17/$C$7 | E18: =E17/$C$7 | F18: =F17/$C$7 | G18: =G17/$C$7
B20: BATCH & THROUGHPUT METRICS
B21: Total Batch Time — STD (hrs) | C21: =C18*C4/60
B22: Total Batch Time — BEST (hrs) | C22: =D18*C4/60
B23: Total Batch Time — WORST (hrs) | C23: =E18*C4/60
B24: Units per 8-hr Day (STD) | C24: =FLOOR(8*60/C18,1)
B25: Labor Cost per Unit (STD) | C25: =G18/$C$7
B26: Labor Cost per Batch (STD) | C26: =G18*C4/$C$7
B27: Custom Mirror Upcharge (min) | C27: =IF(C6=1,'Time Standards'!C17,0)
B29: BOTTLENECK IDENTIFIER
B30: Frame | C30: =C12 | D30: =IF(C12=MAX(C12:C16),"⚠ BOTTLENECK","OK")
B31: Mirrors | C31: =C13 | D31: =IF(C13=MAX(C12:C16),"⚠ BOTTLENECK","OK")
B32: LED Strip | C32: =C14 | D32: =IF(C14=MAX(C12:C16),"⚠ BOTTLENECK","OK")
B33: Controller | C33: =C15 | D33: =IF(C15=MAX(C12:C16),"⚠ BOTTLENECK","OK")
B34: Final Assembly | C34: =C16 | D34: =IF(C16=MAX(C12:C16),"⚠ BOTTLENECK","OK")

Sheet Batch Planner
A1: LED MIRROR — WEEKLY BATCH PLANNER
A2: Plan your weekly production sessions by operation. Inputs pull from Unit Calculator.
B3: WEEKLY DEMAND INPUTS
B4: Orders per Week | C4: 7 | D4: Standard week at 1/day
B5: Working Days per Week | C5: 5 | D5: Available production days
B6: Hours Available/Day | C6: 6 | D6: Net productive hours (not 8 — be realistic)
B8: RECOMMENDED BATCH SCHEDULE
B9: OPERATION | C9: UNITS/BATCH | D9: SESSIONS/WK | E9: HRS/SESSION | F9: TOTAL HRS/WK | G9: NOTES
B10: Frame Build | C10: ='Unit Calculator'!C4 | D10: =CEILING(C3/$C3,1) | E10: =('Unit Calculator'!C4*'Time Standards'!C12/60)/'Unit Calculator'!C7 | F10: =D10*E10 | G10: Cut & mill all frame segments in one pass per batch
B11: Mirror Cutting | C11: ='Unit Calculator'!C4 | D11: =CEILING(C3/$C3,1) | E11: =('Unit Calculator'!C4*'Time Standards'!C19/60)/'Unit Calculator'!C7 | F11: =D11*E11 | G11: Cut full sheets; store 6x6 blanks; custom cut per order
B12: LED Strip Prep | C12: ='Unit Calculator'!C4 | D12: =CEILING(C3/$C3,1) | E12: =('Unit Calculator'!C4*'Time Standards'!C29/60)/'Unit Calculator'!C7 | F12: =D12*E12 | G12: Solder station; batch for efficiency — do full week at once
B13: Controller Prep | C13: ='Unit Calculator'!C4 | D13: =CEILING(C3/$C3,1) | E13: =('Unit Calculator'!C4*'Time Standards'!C37/60)/'Unit Calculator'!C7 | F13: =D13*E13 | G13: Flash in trays; solder same session
B14: Final Assembly | C14: ='Unit Calculator'!C4 | D14: =CEILING(C3/$C3,1) | E14: =('Unit Calculator'!C4*'Time Standards'!C50/60)/'Unit Calculator'!C7 | F14: =D14*E14 | G14: Pull from sub-assembly bins; daily or every 2 days
B15: TOTAL PRODUCTION HRS / WEEK | F15: =SUM(F10:F14)
B17: CAPACITY CHECK
B18: Available Hrs/Week | F18: =C5*C6 | G18: Working days × hrs/day
B19: Required Hrs/Week | F19: =F16 | G19: From batch schedule above
B20: Utilization Rate | F20: =F17/F16 | G20: Target 70–85% for sustainable pace
B21: Headroom (hrs/week) | F21: =F16-F17 | G21: Positive = capacity available
